<?xml version="1.0"?>
<robot xmlns:xacro="http://www.ros.org/wiki/xacro">

    <xacro:property name="base_length" value="0.8" />
    <xacro:property name="base_width" value="0.4" />
    <xacro:property name="base_height" value="0.2" />
    <xacro:property name="wheel_radius" value="0.1" />
    <xacro:property name="wheel_length" value="0.05" />

    <link name="base_footprint" />

    <link name="base_link">
        <visual>
            <geometry>
                <box size="${base_length} ${base_width} ${base_height}" />
            </geometry>
            <origin xyz="0 0 ${base_height / 2.0}" rpy="0 0 0" />
            <material name="blue" />
        </visual>
        <collision>
            <geometry>
                <box size="${base_length} ${base_width} ${base_height}" />
            </geometry>
            <origin xyz="0 0 ${base_height / 2.0}" rpy="0 0 0" />
        </collision>
        <xacro:box_inertia m="5.0" x="${base_length}" y="${base_width}" z="${base_height}"
                           o_xyz="0 0 ${base_height / 2.0}" o_rpy="0 0 0" />
    </link>

    <xacro:macro name="wheel_link" params="prefix">
        <link name="${prefix}_wheel_link">
            <visual>
                <geometry>
                    <cylinder radius="${wheel_radius}" length="${wheel_length}" />
                </geometry>
                <origin xyz="0 0 0" rpy="${pi / 2.0} 0 0" />
                <material name="grey" />
            </visual>
            <collision>
                <geometry>
                    <sphere radius="${wheel_radius}" />
                </geometry>
                <origin xyz="0 0 0" rpy="0 0 0" />
            </collision>
            <xacro:cylinder_inertia m="1.0" r="${wheel_radius}" l="${wheel_length}"
                                    o_xyz="0 0 0" o_rpy="${pi / 2.0} 0 0" />
        </link>
    </xacro:macro>

    <xacro:wheel_link prefix="front_right" />
    <xacro:wheel_link prefix="front_left" />
    <xacro:wheel_link prefix="rear_right" />
    <xacro:wheel_link prefix="rear_left" />

    <!-- <link name="caster_wheel_link">
        <visual>
            <geometry>
                <sphere radius="${wheel_radius / 2.0}" />
            </geometry>
            <origin xyz="0 0 0" rpy="0 0 0" />
            <material name="grey" />
        </visual>
        <collision>
            <geometry>
                <sphere radius="${wheel_radius / 2.0}" />
            </geometry>
            <origin xyz="0 0 0" rpy="0 0 0" />
        </collision>
        <xacro:sphere_inertia m="0.5" r="${wheel_radius / 2.0}"
                              o_xyz="0 0 0" o_rpy="0 0 0" />
    </link> -->

    <joint name="base_joint" type="fixed">
        <parent link="base_footprint" />
        <child link="base_link" />
        <origin xyz="0 0 ${wheel_radius}" rpy="0 0 0"/>
    </joint>

    <joint name="base_rear_right_wheel_joint" type="continuous">
        <parent link="base_link" />
        <child link="rear_right_wheel_link" />
        <origin xyz="${-base_length / 4.0} ${-(base_width + wheel_length) / 2.0} 0" rpy="0 0 0" />
        <axis xyz="0 1 0" />
    </joint>

    <joint name="base_rear_left_wheel_joint" type="continuous">
        <parent link="base_link" />
        <child link="rear_left_wheel_link" />
        <origin xyz="${-base_length / 4.0} ${(base_width + wheel_length) / 2.0} 0" rpy="0 0 0" />
        <axis xyz="0 1 0" />
    </joint>

    <joint name="base_front_right_wheel_joint" type="continuous">
        <parent link="base_link" />
        <child link="front_right_wheel_link" />
        <origin xyz="${base_length / 4.0} ${-(base_width + wheel_length) / 2.0} 0" rpy="0 0 0" />
        <axis xyz="0 1 0" />
    </joint>

    <joint name="base_front_left_wheel_joint" type="continuous">
        <parent link="base_link" />
        <child link="front_left_wheel_link" />
        <origin xyz="${base_length / 4.0} ${(base_width + wheel_length) / 2.0} 0" rpy="0 0 0" />
        <axis xyz="0 1 0" />
    </joint>

    <!-- <joint name="base_caster_wheel_joint" type="fixed">
        <parent link="base_link" />
        <child link="caster_wheel_link" />
        <origin xyz="${base_length / 3.0} 0 ${-wheel_radius / 2.0}" rpy="0 0 0" />
    </joint> -->


    <gazebo reference="front_left_wheel_link">
        <mu1>1.0</mu1>    <!-- forward friction -->
        <mu2>1.0</mu2>    <!-- sideways friction -->
        <kp>1e5</kp>      <!-- contact stiffness -->
        <kd>1.0</kd>      <!-- contact damping -->
        <fdir1>1 0 0</fdir1>
    </gazebo>

    <gazebo reference="front_right_wheel_link">
        <mu1>1.0</mu1>
        <mu2>1.0</mu2>
        <kp>1e5</kp>
        <kd>1.0</kd>
        <fdir1>1 0 0</fdir1>
    </gazebo>

    <gazebo reference="rear_left_wheel_link">
        <mu1>1.0</mu1>
        <mu2>1.0</mu2>
    <kp>1e5</kp>
        <kd>1.0</kd>
        <fdir1>1 0 0</fdir1>
    </gazebo>

    <gazebo reference="rear_right_wheel_link">
        <mu1>1.0</mu1>
        <mu2>1.0</mu2>
        <kp>1e5</kp>
        <kd>1.0</kd>
        <fdir1>1 0 0</fdir1>
    </gazebo>


</robot>