<?xml version="1.0"?>
<robot xmlns:xacro="http://www.ros.org/wiki/xacro">

  <!-- ==================== Robot Properties ==================== -->
  <xacro:property name="chassis_mass"  value="5.0" />
  <xacro:property name="chassis_length" value="0.40" />
  <xacro:property name="chassis_width"  value="0.30" />
  <xacro:property name="chassis_height" value="0.10" />

  <xacro:property name="wheel_mass"   value="0.5" />
  <xacro:property name="wheel_radius" value="0.07" />
  <xacro:property name="wheel_width"  value="0.04" />

  <!-- Wheel positions relative to chassis centre -->
  <xacro:property name="wheel_x_offset" value="0.13" />   <!-- front/rear distance -->
  <xacro:property name="wheel_y_offset" value="0.175" />  <!-- left/right distance -->
  <xacro:property name="wheel_z_offset" value="-0.015" /> <!-- height offset -->

  <!-- ==================== Inertia Macros ==================== -->
  <xacro:macro name="box_inertia" params="m l w h">
    <inertial>
      <origin xyz="0 0 0" rpy="0 0 0"/>
      <mass value="${m}"/>
      <inertia ixx="${(m/12)*(w*w + h*h)}" ixy="0" ixz="0"
               iyy="${(m/12)*(l*l + h*h)}" iyz="0"
               izz="${(m/12)*(l*l + w*w)}"/>
    </inertial>
  </xacro:macro>

  <xacro:macro name="cylinder_inertia" params="m r h">
    <inertial>
      <origin xyz="0 0 0" rpy="0 0 0"/>
      <mass value="${m}"/>
      <inertia ixx="${(m/12)*(3*r*r + h*h)}" ixy="0" ixz="0"
               iyy="${(m/12)*(3*r*r + h*h)}" iyz="0"
               izz="${(m/2)*(r*r)}"/>
    </inertial>
  </xacro:macro>

  <!-- ==================== Wheel Macro ==================== -->
  <xacro:macro name="wheel" params="name x_pos y_pos z_pos">
    <link name="${name}_wheel">
      <visual>
        <geometry>
          <cylinder radius="${wheel_radius}" length="${wheel_width}"/>
        </geometry>
        <origin xyz="0 0 0" rpy="${pi/2} 0 0"/>
        <material name="dark_grey">
          <color rgba="0.2 0.2 0.2 1.0"/>
        </material>
      </visual>
      <collision>
        <geometry>
          <cylinder radius="${wheel_radius}" length="${wheel_width}"/>
        </geometry>
        <origin xyz="0 0 0" rpy="${pi/2} 0 0"/>
      </collision>
      <xacro:cylinder_inertia m="${wheel_mass}" r="${wheel_radius}" h="${wheel_width}"/>
    </link>

    <joint name="${name}_wheel_joint" type="continuous">
      <parent link="base_link"/>
      <child  link="${name}_wheel"/>
      <origin xyz="${x_pos} ${y_pos} ${z_pos}" rpy="0 0 0"/>
      <axis xyz="0 1 0"/>
      <dynamics damping="0.1" friction="0.1"/>
    </joint>
  </xacro:macro>

  <!-- ==================== Base Footprint ==================== -->
  <link name="base_footprint"/>

  <joint name="base_footprint_joint" type="fixed">
    <parent link="base_footprint"/>
    <child  link="base_link"/>
    <origin xyz="0 0 ${wheel_radius + wheel_z_offset}" rpy="0 0 0"/>
  </joint>

  <!-- ==================== Chassis ==================== -->
  <link name="base_link">
    <visual>
      <geometry>
        <box size="${chassis_length} ${chassis_width} ${chassis_height}"/>
      </geometry>
      <origin xyz="0 0 0" rpy="0 0 0"/>
      <material name="blue">
        <color rgba="0.2 0.4 0.8 1.0"/>
      </material>
    </visual>
    <collision>
      <geometry>
        <box size="${chassis_length} ${chassis_width} ${chassis_height}"/>
      </geometry>
      <origin xyz="0 0 0" rpy="0 0 0"/>
    </collision>
    <xacro:box_inertia m="${chassis_mass}" l="${chassis_length}"
                        w="${chassis_width}" h="${chassis_height}"/>
  </link>

  <!-- ==================== Four Wheels ==================== -->
  <xacro:wheel name="front_left"
               x_pos=" ${wheel_x_offset}"
               y_pos=" ${wheel_y_offset}"
               z_pos=" ${wheel_z_offset}"/>

  <xacro:wheel name="front_right"
               x_pos=" ${wheel_x_offset}"
               y_pos="-${wheel_y_offset}"
               z_pos=" ${wheel_z_offset}"/>

  <xacro:wheel name="rear_left"
               x_pos="-${wheel_x_offset}"
               y_pos=" ${wheel_y_offset}"
               z_pos=" ${wheel_z_offset}"/>

  <xacro:wheel name="rear_right"
               x_pos="-${wheel_x_offset}"
               y_pos="-${wheel_y_offset}"
               z_pos=" ${wheel_z_offset}"/>

</robot>
